{
  "uid" : "faf539b10fa7671",
  "name" : "Invalid login - data table",
  "fullName" : "features/tests/Validation.feature:Invalid login - data table",
  "historyId" : "af6cdccb3c63a220aaa53a1d743dbcf7",
  "time" : {
    "start" : 1606689459299,
    "stop" : 1606689473166,
    "duration" : 13867
  },
  "status" : "failed",
  "statusMessage" : "AssertionError: FAILED SUB-STEP: Then I see \"Incorrect username or password entered\" on the page\nSubstep info: Traceback (most recent call last):\n  File \"/opt/hostedtoolcache/Python/3.7.9/x64/lib/python3.7/site-packages/behave/model.py\", line 1806, in run\n    match.run(runner.context)\n  File \"/opt/hostedtoolcache/Python/3.7.9/x64/lib/python3.7/site-packages/behave/matchers.py\", line 97, in run\n    self.func(context, *args, **kwargs)\n  File \"features/steps/basic_steps.py\", line 30, in step_impl\n    ec.text_to_be_present_in_element(element, text), f'Unable to find text: {text}')\n  File \"/opt/hostedtoolcache/Python/3.7.9/x64/lib/python3.7/site-packages/selenium/webdriver/support/wait.py\", line 80, in until\n    raise TimeoutException(message, screen, stacktrace)\nselenium.common.exceptions.TimeoutException: Message: Unable to find text: Incorrect username or password entered\n\n\nTraceback (of failed substep):\n  File \"/opt/hostedtoolcache/Python/3.7.9/x64/lib/python3.7/site-packages/behave/model.py\", line 1806, in run\n    match.run(runner.context)\n  File \"/opt/hostedtoolcache/Python/3.7.9/x64/lib/python3.7/site-packages/behave/matchers.py\", line 97, in run\n    self.func(context, *args, **kwargs)\n  File \"features/steps/basic_steps.py\", line 30, in step_impl\n    ec.text_to_be_present_in_element(element, text), f'Unable to find text: {text}')\n  File \"/opt/hostedtoolcache/Python/3.7.9/x64/lib/python3.7/site-packages/selenium/webdriver/support/wait.py\", line 80, in until\n    raise TimeoutException(message, screen, stacktrace)\n\n",
  "statusTrace" : "  File \"/opt/hostedtoolcache/Python/3.7.9/x64/lib/python3.7/site-packages/behave/model.py\", line 1806, in run\n    match.run(runner.context)\n  File \"/opt/hostedtoolcache/Python/3.7.9/x64/lib/python3.7/site-packages/behave/matchers.py\", line 97, in run\n    self.func(context, *args, **kwargs)\n  File \"features/steps/login_steps.py\", line 35, in step_impl\n    ''')\n  File \"/opt/hostedtoolcache/Python/3.7.9/x64/lib/python3.7/site-packages/behave/runner.py\", line 422, in execute_steps\n    assert False, message\n",
  "flaky" : false,
  "newFailed" : false,
  "beforeStages" : [ ],
  "testStage" : {
    "status" : "failed",
    "statusMessage" : "AssertionError: FAILED SUB-STEP: Then I see \"Incorrect username or password entered\" on the page\nSubstep info: Traceback (most recent call last):\n  File \"/opt/hostedtoolcache/Python/3.7.9/x64/lib/python3.7/site-packages/behave/model.py\", line 1806, in run\n    match.run(runner.context)\n  File \"/opt/hostedtoolcache/Python/3.7.9/x64/lib/python3.7/site-packages/behave/matchers.py\", line 97, in run\n    self.func(context, *args, **kwargs)\n  File \"features/steps/basic_steps.py\", line 30, in step_impl\n    ec.text_to_be_present_in_element(element, text), f'Unable to find text: {text}')\n  File \"/opt/hostedtoolcache/Python/3.7.9/x64/lib/python3.7/site-packages/selenium/webdriver/support/wait.py\", line 80, in until\n    raise TimeoutException(message, screen, stacktrace)\nselenium.common.exceptions.TimeoutException: Message: Unable to find text: Incorrect username or password entered\n\n\nTraceback (of failed substep):\n  File \"/opt/hostedtoolcache/Python/3.7.9/x64/lib/python3.7/site-packages/behave/model.py\", line 1806, in run\n    match.run(runner.context)\n  File \"/opt/hostedtoolcache/Python/3.7.9/x64/lib/python3.7/site-packages/behave/matchers.py\", line 97, in run\n    self.func(context, *args, **kwargs)\n  File \"features/steps/basic_steps.py\", line 30, in step_impl\n    ec.text_to_be_present_in_element(element, text), f'Unable to find text: {text}')\n  File \"/opt/hostedtoolcache/Python/3.7.9/x64/lib/python3.7/site-packages/selenium/webdriver/support/wait.py\", line 80, in until\n    raise TimeoutException(message, screen, stacktrace)\n\n",
    "statusTrace" : "  File \"/opt/hostedtoolcache/Python/3.7.9/x64/lib/python3.7/site-packages/behave/model.py\", line 1806, in run\n    match.run(runner.context)\n  File \"/opt/hostedtoolcache/Python/3.7.9/x64/lib/python3.7/site-packages/behave/matchers.py\", line 97, in run\n    self.func(context, *args, **kwargs)\n  File \"features/steps/login_steps.py\", line 35, in step_impl\n    ''')\n  File \"/opt/hostedtoolcache/Python/3.7.9/x64/lib/python3.7/site-packages/behave/runner.py\", line 422, in execute_steps\n    assert False, message\n",
    "steps" : [ {
      "name" : "Given I open login page",
      "time" : {
        "start" : 1606689459334,
        "stop" : 1606689459947,
        "duration" : 613
      },
      "status" : "passed",
      "steps" : [ ],
      "attachments" : [ ],
      "parameters" : [ ],
      "stepsCount" : 0,
      "attachmentsCount" : 0,
      "shouldDisplayMessage" : false,
      "hasContent" : false
    }, {
      "name" : "Then I see validation message for",
      "time" : {
        "start" : 1606689459947,
        "stop" : 1606689466347,
        "duration" : 6400
      },
      "status" : "failed",
      "statusMessage" : "AssertionError: FAILED SUB-STEP: Then I see \"Incorrect username or password entered\" on the page\nSubstep info: Traceback (most recent call last):\n  File \"/opt/hostedtoolcache/Python/3.7.9/x64/lib/python3.7/site-packages/behave/model.py\", line 1806, in run\n    match.run(runner.context)\n  File \"/opt/hostedtoolcache/Python/3.7.9/x64/lib/python3.7/site-packages/behave/matchers.py\", line 97, in run\n    self.func(context, *args, **kwargs)\n  File \"features/steps/basic_steps.py\", line 30, in step_impl\n    ec.text_to_be_present_in_element(element, text), f'Unable to find text: {text}')\n  File \"/opt/hostedtoolcache/Python/3.7.9/x64/lib/python3.7/site-packages/selenium/webdriver/support/wait.py\", line 80, in until\n    raise TimeoutException(message, screen, stacktrace)\nselenium.common.exceptions.TimeoutException: Message: Unable to find text: Incorrect username or password entered\n\n\nTraceback (of failed substep):\n  File \"/opt/hostedtoolcache/Python/3.7.9/x64/lib/python3.7/site-packages/behave/model.py\", line 1806, in run\n    match.run(runner.context)\n  File \"/opt/hostedtoolcache/Python/3.7.9/x64/lib/python3.7/site-packages/behave/matchers.py\", line 97, in run\n    self.func(context, *args, **kwargs)\n  File \"features/steps/basic_steps.py\", line 30, in step_impl\n    ec.text_to_be_present_in_element(element, text), f'Unable to find text: {text}')\n  File \"/opt/hostedtoolcache/Python/3.7.9/x64/lib/python3.7/site-packages/selenium/webdriver/support/wait.py\", line 80, in until\n    raise TimeoutException(message, screen, stacktrace)\n\n",
      "statusTrace" : "  File \"/opt/hostedtoolcache/Python/3.7.9/x64/lib/python3.7/site-packages/behave/model.py\", line 1806, in run\n    match.run(runner.context)\n  File \"/opt/hostedtoolcache/Python/3.7.9/x64/lib/python3.7/site-packages/behave/matchers.py\", line 97, in run\n    self.func(context, *args, **kwargs)\n  File \"features/steps/login_steps.py\", line 35, in step_impl\n    ''')\n  File \"/opt/hostedtoolcache/Python/3.7.9/x64/lib/python3.7/site-packages/behave/runner.py\", line 422, in execute_steps\n    assert False, message\n",
      "steps" : [ ],
      "attachments" : [ {
        "uid" : "ae29dd810ec66719",
        "name" : ".table",
        "source" : "ae29dd810ec66719.csv",
        "type" : "text/csv",
        "size" : 220
      }, {
        "uid" : "4e10386736004ca2",
        "name" : "bug.png",
        "source" : "4e10386736004ca2.png",
        "type" : "image/png",
        "size" : 99879
      }, {
        "uid" : "9e110a0c99850caa",
        "name" : "bug.png",
        "source" : "9e110a0c99850caa.png",
        "type" : "image/png",
        "size" : 99879
      } ],
      "parameters" : [ ],
      "stepsCount" : 0,
      "attachmentsCount" : 3,
      "shouldDisplayMessage" : true,
      "hasContent" : true
    }, {
      "name" : "Given I open login page",
      "time" : {
        "start" : 1606689466392,
        "stop" : 1606689466837,
        "duration" : 445
      },
      "status" : "passed",
      "steps" : [ ],
      "attachments" : [ ],
      "parameters" : [ ],
      "stepsCount" : 0,
      "attachmentsCount" : 0,
      "shouldDisplayMessage" : false,
      "hasContent" : false
    }, {
      "name" : "Then I see validation message for",
      "time" : {
        "start" : 1606689466837,
        "stop" : 1606689473166,
        "duration" : 6329
      },
      "status" : "failed",
      "statusMessage" : "AssertionError: FAILED SUB-STEP: Then I see \"Incorrect username or password entered\" on the page\nSubstep info: Traceback (most recent call last):\n  File \"/opt/hostedtoolcache/Python/3.7.9/x64/lib/python3.7/site-packages/behave/model.py\", line 1806, in run\n    match.run(runner.context)\n  File \"/opt/hostedtoolcache/Python/3.7.9/x64/lib/python3.7/site-packages/behave/matchers.py\", line 97, in run\n    self.func(context, *args, **kwargs)\n  File \"features/steps/basic_steps.py\", line 30, in step_impl\n    ec.text_to_be_present_in_element(element, text), f'Unable to find text: {text}')\n  File \"/opt/hostedtoolcache/Python/3.7.9/x64/lib/python3.7/site-packages/selenium/webdriver/support/wait.py\", line 80, in until\n    raise TimeoutException(message, screen, stacktrace)\nselenium.common.exceptions.TimeoutException: Message: Unable to find text: Incorrect username or password entered\n\n\nTraceback (of failed substep):\n  File \"/opt/hostedtoolcache/Python/3.7.9/x64/lib/python3.7/site-packages/behave/model.py\", line 1806, in run\n    match.run(runner.context)\n  File \"/opt/hostedtoolcache/Python/3.7.9/x64/lib/python3.7/site-packages/behave/matchers.py\", line 97, in run\n    self.func(context, *args, **kwargs)\n  File \"features/steps/basic_steps.py\", line 30, in step_impl\n    ec.text_to_be_present_in_element(element, text), f'Unable to find text: {text}')\n  File \"/opt/hostedtoolcache/Python/3.7.9/x64/lib/python3.7/site-packages/selenium/webdriver/support/wait.py\", line 80, in until\n    raise TimeoutException(message, screen, stacktrace)\n\n",
      "statusTrace" : "  File \"/opt/hostedtoolcache/Python/3.7.9/x64/lib/python3.7/site-packages/behave/model.py\", line 1806, in run\n    match.run(runner.context)\n  File \"/opt/hostedtoolcache/Python/3.7.9/x64/lib/python3.7/site-packages/behave/matchers.py\", line 97, in run\n    self.func(context, *args, **kwargs)\n  File \"features/steps/login_steps.py\", line 35, in step_impl\n    ''')\n  File \"/opt/hostedtoolcache/Python/3.7.9/x64/lib/python3.7/site-packages/behave/runner.py\", line 422, in execute_steps\n    assert False, message\n",
      "steps" : [ ],
      "attachments" : [ {
        "uid" : "7846b76798836127",
        "name" : ".table",
        "source" : "7846b76798836127.csv",
        "type" : "text/csv",
        "size" : 220
      }, {
        "uid" : "4a11290c3a53d325",
        "name" : "bug.png",
        "source" : "4a11290c3a53d325.png",
        "type" : "image/png",
        "size" : 98345
      }, {
        "uid" : "6461b36f605c3bf4",
        "name" : "bug.png",
        "source" : "6461b36f605c3bf4.png",
        "type" : "image/png",
        "size" : 98345
      } ],
      "parameters" : [ ],
      "stepsCount" : 0,
      "attachmentsCount" : 3,
      "shouldDisplayMessage" : true,
      "hasContent" : true
    } ],
    "attachments" : [ ],
    "parameters" : [ ],
    "stepsCount" : 4,
    "attachmentsCount" : 6,
    "shouldDisplayMessage" : false,
    "hasContent" : true
  },
  "afterStages" : [ ],
  "labels" : [ {
    "name" : "severity",
    "value" : "normal"
  }, {
    "name" : "tag",
    "value" : "regression"
  }, {
    "name" : "feature",
    "value" : "Login"
  }, {
    "name" : "framework",
    "value" : "behave"
  }, {
    "name" : "language",
    "value" : "cpython3"
  }, {
    "name" : "resultFormat",
    "value" : "allure2"
  } ],
  "parameters" : [ ],
  "links" : [ ],
  "hidden" : false,
  "retry" : false,
  "extra" : {
    "severity" : "normal",
    "retries" : [ ],
    "categories" : [ {
      "name" : "Product defects",
      "matchedStatuses" : [ ],
      "flaky" : false
    } ],
    "tags" : [ "regression" ]
  },
  "source" : "faf539b10fa7671.json",
  "parameterValues" : [ ]
}